Mon Dec  4 12:39:01 2023
KeyError
Traceback (most recent call last):
  File "C:\Users\user\PycharmProjects\python_basic_diploma\handlers\default_handlers\search_commands.py", line 20, in main_search_command
    data["cond"] = msg_user
    ~~~~^^^^^^^^
TypeError: 'NoneType' object does not support item assignment

During handling of the above exception, another exception occurred:

Traceback (most recent call last):
  File "C:\Users\user\PycharmProjects\python_basic_diploma\handlers\default_handlers\exception_handler.py", line 21, in wrapped
    method(message)
  File "C:\Users\user\PycharmProjects\python_basic_diploma\handlers\default_handlers\search_commands.py", line 19, in main_search_command
    with bot.retrieve_data(user_id=user_id, chat_id=chat_id) as data:
  File "C:\Users\user\PycharmProjects\python_basic_diploma\venv\Lib\site-packages\telebot\storage\base_storage.py", line 68, in __exit__
    return self.obj.save(self.chat_id, self.user_id, self.data)
           ^^^^^^^^^^^^^^^^^^^^^^^^^^^^^^^^^^^^^^^^^^^^^^^^^^^^
  File "C:\Users\user\PycharmProjects\python_basic_diploma\venv\Lib\site-packages\telebot\storage\memory_storage.py", line 69, in save
    self.data[chat_id][user_id]['data'] = data
    ~~~~~~~~~^^^^^^^^^
KeyError: 439024736



Mon Dec  4 12:52:45 2023
KeyError
Traceback (most recent call last):
  File "C:\Users\user\PycharmProjects\python_basic_diploma\handlers\default_handlers\search_commands.py", line 21, in main_search_command
    data["cond"] = msg_user
    ~~~~^^^^^^^^
TypeError: 'NoneType' object does not support item assignment

During handling of the above exception, another exception occurred:

Traceback (most recent call last):
  File "C:\Users\user\PycharmProjects\python_basic_diploma\handlers\default_handlers\exception_handler.py", line 21, in wrapped
    method(message)
  File "C:\Users\user\PycharmProjects\python_basic_diploma\handlers\default_handlers\search_commands.py", line 20, in main_search_command
    with bot.retrieve_data(user_id=user_id, chat_id=chat_id) as data:
  File "C:\Users\user\PycharmProjects\python_basic_diploma\venv\Lib\site-packages\telebot\storage\base_storage.py", line 68, in __exit__
    return self.obj.save(self.chat_id, self.user_id, self.data)
           ^^^^^^^^^^^^^^^^^^^^^^^^^^^^^^^^^^^^^^^^^^^^^^^^^^^^
  File "C:\Users\user\PycharmProjects\python_basic_diploma\venv\Lib\site-packages\telebot\storage\memory_storage.py", line 69, in save
    self.data[chat_id][user_id]['data'] = data
    ~~~~~~~~~^^^^^^^^^
KeyError: 439024736



Thu Dec  7 12:19:41 2023
KeyError
Traceback (most recent call last):
  File "C:\Users\user\PycharmProjects\python_basic_diploma\handlers\default_handlers\search_commands.py", line 22, in main_search_command
    data["cond"] = msg_user
    ~~~~^^^^^^^^
TypeError: 'NoneType' object does not support item assignment

During handling of the above exception, another exception occurred:

Traceback (most recent call last):
  File "C:\Users\user\PycharmProjects\python_basic_diploma\handlers\default_handlers\exception_handler.py", line 21, in wrapped
    method(message)
  File "C:\Users\user\PycharmProjects\python_basic_diploma\handlers\default_handlers\search_commands.py", line 21, in main_search_command
    with bot.retrieve_data(user_id=user_id, chat_id=chat_id) as data:
  File "C:\Users\user\PycharmProjects\python_basic_diploma\venv\Lib\site-packages\telebot\storage\base_storage.py", line 68, in __exit__
    return self.obj.save(self.chat_id, self.user_id, self.data)
           ^^^^^^^^^^^^^^^^^^^^^^^^^^^^^^^^^^^^^^^^^^^^^^^^^^^^
  File "C:\Users\user\PycharmProjects\python_basic_diploma\venv\Lib\site-packages\telebot\storage\memory_storage.py", line 69, in save
    self.data[chat_id][user_id]['data'] = data
    ~~~~~~~~~^^^^^^^^^
KeyError: 439024736



Thu Dec  7 13:08:06 2023
KeyError
Traceback (most recent call last):
  File "C:\Users\user\PycharmProjects\python_basic_diploma\handlers\additional_handlers\price_rating.py", line 20, in main_search_command
    data["cond"] = "_less_than"
    ~~~~^^^^^^^^
TypeError: 'NoneType' object does not support item assignment

During handling of the above exception, another exception occurred:

Traceback (most recent call last):
  File "C:\Users\user\PycharmProjects\python_basic_diploma\handlers\default_handlers\exception_handler.py", line 21, in wrapped
    method(message)
  File "C:\Users\user\PycharmProjects\python_basic_diploma\handlers\additional_handlers\price_rating.py", line 18, in main_search_command
    with bot.retrieve_data(user_id=user_id, chat_id=chat_id) as data:
  File "C:\Users\user\PycharmProjects\python_basic_diploma\venv\Lib\site-packages\telebot\storage\base_storage.py", line 68, in __exit__
    return self.obj.save(self.chat_id, self.user_id, self.data)
           ^^^^^^^^^^^^^^^^^^^^^^^^^^^^^^^^^^^^^^^^^^^^^^^^^^^^
  File "C:\Users\user\PycharmProjects\python_basic_diploma\venv\Lib\site-packages\telebot\storage\memory_storage.py", line 69, in save
    self.data[chat_id][user_id]['data'] = data
    ~~~~~~~~~^^^^^^^^^
KeyError: 439024736



Thu Dec  7 13:09:33 2023
KeyError
Traceback (most recent call last):
  File "C:\Users\user\PycharmProjects\python_basic_diploma\handlers\additional_handlers\price_rating.py", line 20, in main_search_command
    data["cond"] = "_less_than"
    ~~~~^^^^^^^^
TypeError: 'NoneType' object does not support item assignment

During handling of the above exception, another exception occurred:

Traceback (most recent call last):
  File "C:\Users\user\PycharmProjects\python_basic_diploma\handlers\default_handlers\exception_handler.py", line 21, in wrapped
    method(message)
  File "C:\Users\user\PycharmProjects\python_basic_diploma\handlers\additional_handlers\price_rating.py", line 18, in main_search_command
    with bot.retrieve_data(user_id=user_id, chat_id=chat_id) as data:
  File "C:\Users\user\PycharmProjects\python_basic_diploma\venv\Lib\site-packages\telebot\storage\base_storage.py", line 68, in __exit__
    return self.obj.save(self.chat_id, self.user_id, self.data)
           ^^^^^^^^^^^^^^^^^^^^^^^^^^^^^^^^^^^^^^^^^^^^^^^^^^^^
  File "C:\Users\user\PycharmProjects\python_basic_diploma\venv\Lib\site-packages\telebot\storage\memory_storage.py", line 69, in save
    self.data[chat_id][user_id]['data'] = data
    ~~~~~~~~~^^^^^^^^^
KeyError: 439024736



Thu Dec  7 13:12:51 2023
KeyError
Traceback (most recent call last):
  File "C:\Users\user\PycharmProjects\python_basic_diploma\handlers\default_handlers\search_commands.py", line 22, in main_search_command
    data["cond"] = msg_user
    ~~~~^^^^^^^^
TypeError: 'NoneType' object does not support item assignment

During handling of the above exception, another exception occurred:

Traceback (most recent call last):
  File "C:\Users\user\PycharmProjects\python_basic_diploma\handlers\default_handlers\exception_handler.py", line 21, in wrapped
    method(message)
  File "C:\Users\user\PycharmProjects\python_basic_diploma\handlers\default_handlers\search_commands.py", line 21, in main_search_command
    with bot.retrieve_data(user_id=user_id, chat_id=chat_id) as data:
  File "C:\Users\user\PycharmProjects\python_basic_diploma\venv\Lib\site-packages\telebot\storage\base_storage.py", line 68, in __exit__
    return self.obj.save(self.chat_id, self.user_id, self.data)
           ^^^^^^^^^^^^^^^^^^^^^^^^^^^^^^^^^^^^^^^^^^^^^^^^^^^^
  File "C:\Users\user\PycharmProjects\python_basic_diploma\venv\Lib\site-packages\telebot\storage\memory_storage.py", line 69, in save
    self.data[chat_id][user_id]['data'] = data
    ~~~~~~~~~^^^^^^^^^
KeyError: 439024736



Thu Dec  7 13:14:25 2023
KeyError
Traceback (most recent call last):
  File "C:\Users\user\PycharmProjects\python_basic_diploma\handlers\default_handlers\search_commands.py", line 22, in main_search_command
    data["cond"] = msg_user
    ~~~~^^^^^^^^
TypeError: 'NoneType' object does not support item assignment

During handling of the above exception, another exception occurred:

Traceback (most recent call last):
  File "C:\Users\user\PycharmProjects\python_basic_diploma\handlers\default_handlers\exception_handler.py", line 21, in wrapped
    method(message)
  File "C:\Users\user\PycharmProjects\python_basic_diploma\handlers\default_handlers\search_commands.py", line 21, in main_search_command
    with bot.retrieve_data(user_id=user_id, chat_id=chat_id) as data:
  File "C:\Users\user\PycharmProjects\python_basic_diploma\venv\Lib\site-packages\telebot\storage\base_storage.py", line 68, in __exit__
    return self.obj.save(self.chat_id, self.user_id, self.data)
           ^^^^^^^^^^^^^^^^^^^^^^^^^^^^^^^^^^^^^^^^^^^^^^^^^^^^
  File "C:\Users\user\PycharmProjects\python_basic_diploma\venv\Lib\site-packages\telebot\storage\memory_storage.py", line 69, in save
    self.data[chat_id][user_id]['data'] = data
    ~~~~~~~~~^^^^^^^^^
KeyError: 439024736



Thu Dec  7 18:43:28 2023
KeyError
Traceback (most recent call last):
  File "C:\Users\user\PycharmProjects\python_basic_diploma\handlers\default_handlers\search_commands.py", line 22, in main_search_command
    data["cond"] = msg_user
    ~~~~^^^^^^^^
TypeError: 'NoneType' object does not support item assignment

During handling of the above exception, another exception occurred:

Traceback (most recent call last):
  File "C:\Users\user\PycharmProjects\python_basic_diploma\handlers\default_handlers\exception_handler.py", line 21, in wrapped
    method(message)
  File "C:\Users\user\PycharmProjects\python_basic_diploma\handlers\default_handlers\search_commands.py", line 21, in main_search_command
    with bot.retrieve_data(user_id=user_id, chat_id=chat_id) as data:
  File "C:\Users\user\PycharmProjects\python_basic_diploma\venv\Lib\site-packages\telebot\storage\base_storage.py", line 68, in __exit__
    return self.obj.save(self.chat_id, self.user_id, self.data)
           ^^^^^^^^^^^^^^^^^^^^^^^^^^^^^^^^^^^^^^^^^^^^^^^^^^^^
  File "C:\Users\user\PycharmProjects\python_basic_diploma\venv\Lib\site-packages\telebot\storage\memory_storage.py", line 69, in save
    self.data[chat_id][user_id]['data'] = data
    ~~~~~~~~~^^^^^^^^^
KeyError: 439024736



Thu Dec  7 18:46:18 2023
KeyError
Traceback (most recent call last):
  File "C:\Users\user\PycharmProjects\python_basic_diploma\handlers\default_handlers\search_commands.py", line 22, in main_search_command
    data["cond"] = msg_user
    ~~~~^^^^^^^^
TypeError: 'NoneType' object does not support item assignment

During handling of the above exception, another exception occurred:

Traceback (most recent call last):
  File "C:\Users\user\PycharmProjects\python_basic_diploma\handlers\default_handlers\exception_handler.py", line 21, in wrapped
    method(message)
  File "C:\Users\user\PycharmProjects\python_basic_diploma\handlers\default_handlers\search_commands.py", line 21, in main_search_command
    with bot.retrieve_data(user_id=user_id, chat_id=chat_id) as data:
  File "C:\Users\user\PycharmProjects\python_basic_diploma\venv\Lib\site-packages\telebot\storage\base_storage.py", line 68, in __exit__
    return self.obj.save(self.chat_id, self.user_id, self.data)
           ^^^^^^^^^^^^^^^^^^^^^^^^^^^^^^^^^^^^^^^^^^^^^^^^^^^^
  File "C:\Users\user\PycharmProjects\python_basic_diploma\venv\Lib\site-packages\telebot\storage\memory_storage.py", line 69, in save
    self.data[chat_id][user_id]['data'] = data
    ~~~~~~~~~^^^^^^^^^
KeyError: 439024736



Thu Dec  7 18:47:13 2023
KeyError
Traceback (most recent call last):
  File "C:\Users\user\PycharmProjects\python_basic_diploma\handlers\default_handlers\search_commands.py", line 22, in main_search_command
    data["cond"] = msg_user
    ~~~~^^^^^^^^
TypeError: 'NoneType' object does not support item assignment

During handling of the above exception, another exception occurred:

Traceback (most recent call last):
  File "C:\Users\user\PycharmProjects\python_basic_diploma\handlers\default_handlers\exception_handler.py", line 21, in wrapped
    method(message)
  File "C:\Users\user\PycharmProjects\python_basic_diploma\handlers\default_handlers\search_commands.py", line 21, in main_search_command
    with bot.retrieve_data(user_id=user_id, chat_id=chat_id) as data:
  File "C:\Users\user\PycharmProjects\python_basic_diploma\venv\Lib\site-packages\telebot\storage\base_storage.py", line 68, in __exit__
    return self.obj.save(self.chat_id, self.user_id, self.data)
           ^^^^^^^^^^^^^^^^^^^^^^^^^^^^^^^^^^^^^^^^^^^^^^^^^^^^
  File "C:\Users\user\PycharmProjects\python_basic_diploma\venv\Lib\site-packages\telebot\storage\memory_storage.py", line 69, in save
    self.data[chat_id][user_id]['data'] = data
    ~~~~~~~~~^^^^^^^^^
KeyError: 439024736



Thu Dec  7 18:53:30 2023
KeyError
Traceback (most recent call last):
  File "C:\Users\user\PycharmProjects\python_basic_diploma\handlers\default_handlers\search_commands.py", line 23, in main_search_command
    data["cond"] = msg_user
    ~~~~^^^^^^^^
TypeError: 'NoneType' object does not support item assignment

During handling of the above exception, another exception occurred:

Traceback (most recent call last):
  File "C:\Users\user\PycharmProjects\python_basic_diploma\handlers\default_handlers\exception_handler.py", line 21, in wrapped
    method(message)
  File "C:\Users\user\PycharmProjects\python_basic_diploma\handlers\default_handlers\search_commands.py", line 22, in main_search_command
    with bot.retrieve_data(user_id=user_id, chat_id=chat_id) as data:
  File "C:\Users\user\PycharmProjects\python_basic_diploma\venv\Lib\site-packages\telebot\storage\base_storage.py", line 68, in __exit__
    return self.obj.save(self.chat_id, self.user_id, self.data)
           ^^^^^^^^^^^^^^^^^^^^^^^^^^^^^^^^^^^^^^^^^^^^^^^^^^^^
  File "C:\Users\user\PycharmProjects\python_basic_diploma\venv\Lib\site-packages\telebot\storage\memory_storage.py", line 69, in save
    self.data[chat_id][user_id]['data'] = data
    ~~~~~~~~~^^^^^^^^^
KeyError: 439024736



