Mon Dec 11 13:16:22 2023
KeyError
Traceback (most recent call last):
  File "C:\Users\user\PycharmProjects\python_basic_diploma\handlers\additional_handlers\price_rating.py", line 19, in main_search_command
    data["cond2"] = "_less_than"
    ~~~~^^^^^^^^^
TypeError: 'NoneType' object does not support item assignment

During handling of the above exception, another exception occurred:

Traceback (most recent call last):
  File "C:\Users\user\PycharmProjects\python_basic_diploma\handlers\default_handlers\exception_handler.py", line 17, in wrapped
    method(message)
  File "C:\Users\user\PycharmProjects\python_basic_diploma\handlers\additional_handlers\price_rating.py", line 17, in main_search_command
    with bot.retrieve_data(user_id=user_id, chat_id=chat_id) as data:
  File "C:\Users\user\PycharmProjects\python_basic_diploma\venv\Lib\site-packages\telebot\storage\base_storage.py", line 68, in __exit__
    return self.obj.save(self.chat_id, self.user_id, self.data)
           ^^^^^^^^^^^^^^^^^^^^^^^^^^^^^^^^^^^^^^^^^^^^^^^^^^^^
  File "C:\Users\user\PycharmProjects\python_basic_diploma\venv\Lib\site-packages\telebot\storage\memory_storage.py", line 69, in save
    self.data[chat_id][user_id]['data'] = data
    ~~~~~~~~~^^^^^^^^^
KeyError: 439024736



Mon Dec 11 13:16:26 2023
IntegrityError
Traceback (most recent call last):
  File "C:\Users\user\PycharmProjects\python_basic_diploma\venv\Lib\site-packages\peewee.py", line 3251, in execute_sql
    cursor.execute(sql, params or ())
sqlite3.IntegrityError: UNIQUE constraint failed: user.user_id

During handling of the above exception, another exception occurred:

Traceback (most recent call last):
  File "C:\Users\user\PycharmProjects\python_basic_diploma\handlers\default_handlers\exception_handler.py", line 17, in wrapped
    method(message)
  File "C:\Users\user\PycharmProjects\python_basic_diploma\handlers\default_handlers\start_commands.py", line 25, in start_command_handler
    User(user_id=user_id, username=username, first_name=first_name, last_name=last_name).save()
  File "C:\Users\user\PycharmProjects\python_basic_diploma\venv\Lib\site-packages\peewee.py", line 6806, in save
    pk = self.insert(**field_dict).execute()
         ^^^^^^^^^^^^^^^^^^^^^^^^^^^^^^^^^^^
  File "C:\Users\user\PycharmProjects\python_basic_diploma\venv\Lib\site-packages\peewee.py", line 1971, in inner
    return method(self, database, *args, **kwargs)
           ^^^^^^^^^^^^^^^^^^^^^^^^^^^^^^^^^^^^^^^
  File "C:\Users\user\PycharmProjects\python_basic_diploma\venv\Lib\site-packages\peewee.py", line 2042, in execute
    return self._execute(database)
           ^^^^^^^^^^^^^^^^^^^^^^^
  File "C:\Users\user\PycharmProjects\python_basic_diploma\venv\Lib\site-packages\peewee.py", line 2847, in _execute
    return super(Insert, self)._execute(database)
           ^^^^^^^^^^^^^^^^^^^^^^^^^^^^^^^^^^^^^^
  File "C:\Users\user\PycharmProjects\python_basic_diploma\venv\Lib\site-packages\peewee.py", line 2560, in _execute
    cursor = database.execute(self)
             ^^^^^^^^^^^^^^^^^^^^^^
  File "C:\Users\user\PycharmProjects\python_basic_diploma\venv\Lib\site-packages\peewee.py", line 3259, in execute
    return self.execute_sql(sql, params)
           ^^^^^^^^^^^^^^^^^^^^^^^^^^^^^
  File "C:\Users\user\PycharmProjects\python_basic_diploma\venv\Lib\site-packages\peewee.py", line 3249, in execute_sql
    with __exception_wrapper__:
  File "C:\Users\user\PycharmProjects\python_basic_diploma\venv\Lib\site-packages\peewee.py", line 3019, in __exit__
    reraise(new_type, new_type(exc_value, *exc_args), traceback)
  File "C:\Users\user\PycharmProjects\python_basic_diploma\venv\Lib\site-packages\peewee.py", line 192, in reraise
    raise value.with_traceback(tb)
  File "C:\Users\user\PycharmProjects\python_basic_diploma\venv\Lib\site-packages\peewee.py", line 3251, in execute_sql
    cursor.execute(sql, params or ())
peewee.IntegrityError: UNIQUE constraint failed: user.user_id



Mon Dec 11 13:16:28 2023
IntegrityError
Traceback (most recent call last):
  File "C:\Users\user\PycharmProjects\python_basic_diploma\venv\Lib\site-packages\peewee.py", line 3251, in execute_sql
    cursor.execute(sql, params or ())
sqlite3.IntegrityError: UNIQUE constraint failed: user.user_id

During handling of the above exception, another exception occurred:

Traceback (most recent call last):
  File "C:\Users\user\PycharmProjects\python_basic_diploma\handlers\default_handlers\exception_handler.py", line 17, in wrapped
    method(message)
  File "C:\Users\user\PycharmProjects\python_basic_diploma\handlers\default_handlers\start_commands.py", line 25, in start_command_handler
    User(user_id=user_id, username=username, first_name=first_name, last_name=last_name).save()
  File "C:\Users\user\PycharmProjects\python_basic_diploma\venv\Lib\site-packages\peewee.py", line 6806, in save
    pk = self.insert(**field_dict).execute()
         ^^^^^^^^^^^^^^^^^^^^^^^^^^^^^^^^^^^
  File "C:\Users\user\PycharmProjects\python_basic_diploma\venv\Lib\site-packages\peewee.py", line 1971, in inner
    return method(self, database, *args, **kwargs)
           ^^^^^^^^^^^^^^^^^^^^^^^^^^^^^^^^^^^^^^^
  File "C:\Users\user\PycharmProjects\python_basic_diploma\venv\Lib\site-packages\peewee.py", line 2042, in execute
    return self._execute(database)
           ^^^^^^^^^^^^^^^^^^^^^^^
  File "C:\Users\user\PycharmProjects\python_basic_diploma\venv\Lib\site-packages\peewee.py", line 2847, in _execute
    return super(Insert, self)._execute(database)
           ^^^^^^^^^^^^^^^^^^^^^^^^^^^^^^^^^^^^^^
  File "C:\Users\user\PycharmProjects\python_basic_diploma\venv\Lib\site-packages\peewee.py", line 2560, in _execute
    cursor = database.execute(self)
             ^^^^^^^^^^^^^^^^^^^^^^
  File "C:\Users\user\PycharmProjects\python_basic_diploma\venv\Lib\site-packages\peewee.py", line 3259, in execute
    return self.execute_sql(sql, params)
           ^^^^^^^^^^^^^^^^^^^^^^^^^^^^^
  File "C:\Users\user\PycharmProjects\python_basic_diploma\venv\Lib\site-packages\peewee.py", line 3249, in execute_sql
    with __exception_wrapper__:
  File "C:\Users\user\PycharmProjects\python_basic_diploma\venv\Lib\site-packages\peewee.py", line 3019, in __exit__
    reraise(new_type, new_type(exc_value, *exc_args), traceback)
  File "C:\Users\user\PycharmProjects\python_basic_diploma\venv\Lib\site-packages\peewee.py", line 192, in reraise
    raise value.with_traceback(tb)
  File "C:\Users\user\PycharmProjects\python_basic_diploma\venv\Lib\site-packages\peewee.py", line 3251, in execute_sql
    cursor.execute(sql, params or ())
peewee.IntegrityError: UNIQUE constraint failed: user.user_id



Mon Dec 11 13:16:29 2023
IntegrityError
Traceback (most recent call last):
  File "C:\Users\user\PycharmProjects\python_basic_diploma\venv\Lib\site-packages\peewee.py", line 3251, in execute_sql
    cursor.execute(sql, params or ())
sqlite3.IntegrityError: UNIQUE constraint failed: user.user_id

During handling of the above exception, another exception occurred:

Traceback (most recent call last):
  File "C:\Users\user\PycharmProjects\python_basic_diploma\handlers\default_handlers\exception_handler.py", line 17, in wrapped
    method(message)
  File "C:\Users\user\PycharmProjects\python_basic_diploma\handlers\default_handlers\start_commands.py", line 25, in start_command_handler
    User(user_id=user_id, username=username, first_name=first_name, last_name=last_name).save()
  File "C:\Users\user\PycharmProjects\python_basic_diploma\venv\Lib\site-packages\peewee.py", line 6806, in save
    pk = self.insert(**field_dict).execute()
         ^^^^^^^^^^^^^^^^^^^^^^^^^^^^^^^^^^^
  File "C:\Users\user\PycharmProjects\python_basic_diploma\venv\Lib\site-packages\peewee.py", line 1971, in inner
    return method(self, database, *args, **kwargs)
           ^^^^^^^^^^^^^^^^^^^^^^^^^^^^^^^^^^^^^^^
  File "C:\Users\user\PycharmProjects\python_basic_diploma\venv\Lib\site-packages\peewee.py", line 2042, in execute
    return self._execute(database)
           ^^^^^^^^^^^^^^^^^^^^^^^
  File "C:\Users\user\PycharmProjects\python_basic_diploma\venv\Lib\site-packages\peewee.py", line 2847, in _execute
    return super(Insert, self)._execute(database)
           ^^^^^^^^^^^^^^^^^^^^^^^^^^^^^^^^^^^^^^
  File "C:\Users\user\PycharmProjects\python_basic_diploma\venv\Lib\site-packages\peewee.py", line 2560, in _execute
    cursor = database.execute(self)
             ^^^^^^^^^^^^^^^^^^^^^^
  File "C:\Users\user\PycharmProjects\python_basic_diploma\venv\Lib\site-packages\peewee.py", line 3259, in execute
    return self.execute_sql(sql, params)
           ^^^^^^^^^^^^^^^^^^^^^^^^^^^^^
  File "C:\Users\user\PycharmProjects\python_basic_diploma\venv\Lib\site-packages\peewee.py", line 3249, in execute_sql
    with __exception_wrapper__:
  File "C:\Users\user\PycharmProjects\python_basic_diploma\venv\Lib\site-packages\peewee.py", line 3019, in __exit__
    reraise(new_type, new_type(exc_value, *exc_args), traceback)
  File "C:\Users\user\PycharmProjects\python_basic_diploma\venv\Lib\site-packages\peewee.py", line 192, in reraise
    raise value.with_traceback(tb)
  File "C:\Users\user\PycharmProjects\python_basic_diploma\venv\Lib\site-packages\peewee.py", line 3251, in execute_sql
    cursor.execute(sql, params or ())
peewee.IntegrityError: UNIQUE constraint failed: user.user_id



Mon Dec 11 13:16:30 2023
IntegrityError
Traceback (most recent call last):
  File "C:\Users\user\PycharmProjects\python_basic_diploma\venv\Lib\site-packages\peewee.py", line 3251, in execute_sql
    cursor.execute(sql, params or ())
sqlite3.IntegrityError: UNIQUE constraint failed: user.user_id

During handling of the above exception, another exception occurred:

Traceback (most recent call last):
  File "C:\Users\user\PycharmProjects\python_basic_diploma\handlers\default_handlers\exception_handler.py", line 17, in wrapped
    method(message)
  File "C:\Users\user\PycharmProjects\python_basic_diploma\handlers\default_handlers\start_commands.py", line 25, in start_command_handler
    User(user_id=user_id, username=username, first_name=first_name, last_name=last_name).save()
  File "C:\Users\user\PycharmProjects\python_basic_diploma\venv\Lib\site-packages\peewee.py", line 6806, in save
    pk = self.insert(**field_dict).execute()
         ^^^^^^^^^^^^^^^^^^^^^^^^^^^^^^^^^^^
  File "C:\Users\user\PycharmProjects\python_basic_diploma\venv\Lib\site-packages\peewee.py", line 1971, in inner
    return method(self, database, *args, **kwargs)
           ^^^^^^^^^^^^^^^^^^^^^^^^^^^^^^^^^^^^^^^
  File "C:\Users\user\PycharmProjects\python_basic_diploma\venv\Lib\site-packages\peewee.py", line 2042, in execute
    return self._execute(database)
           ^^^^^^^^^^^^^^^^^^^^^^^
  File "C:\Users\user\PycharmProjects\python_basic_diploma\venv\Lib\site-packages\peewee.py", line 2847, in _execute
    return super(Insert, self)._execute(database)
           ^^^^^^^^^^^^^^^^^^^^^^^^^^^^^^^^^^^^^^
  File "C:\Users\user\PycharmProjects\python_basic_diploma\venv\Lib\site-packages\peewee.py", line 2560, in _execute
    cursor = database.execute(self)
             ^^^^^^^^^^^^^^^^^^^^^^
  File "C:\Users\user\PycharmProjects\python_basic_diploma\venv\Lib\site-packages\peewee.py", line 3259, in execute
    return self.execute_sql(sql, params)
           ^^^^^^^^^^^^^^^^^^^^^^^^^^^^^
  File "C:\Users\user\PycharmProjects\python_basic_diploma\venv\Lib\site-packages\peewee.py", line 3249, in execute_sql
    with __exception_wrapper__:
  File "C:\Users\user\PycharmProjects\python_basic_diploma\venv\Lib\site-packages\peewee.py", line 3019, in __exit__
    reraise(new_type, new_type(exc_value, *exc_args), traceback)
  File "C:\Users\user\PycharmProjects\python_basic_diploma\venv\Lib\site-packages\peewee.py", line 192, in reraise
    raise value.with_traceback(tb)
  File "C:\Users\user\PycharmProjects\python_basic_diploma\venv\Lib\site-packages\peewee.py", line 3251, in execute_sql
    cursor.execute(sql, params or ())
peewee.IntegrityError: UNIQUE constraint failed: user.user_id



Mon Dec 11 13:16:31 2023
IntegrityError
Traceback (most recent call last):
  File "C:\Users\user\PycharmProjects\python_basic_diploma\venv\Lib\site-packages\peewee.py", line 3251, in execute_sql
    cursor.execute(sql, params or ())
sqlite3.IntegrityError: UNIQUE constraint failed: user.user_id

During handling of the above exception, another exception occurred:

Traceback (most recent call last):
  File "C:\Users\user\PycharmProjects\python_basic_diploma\handlers\default_handlers\exception_handler.py", line 17, in wrapped
    method(message)
  File "C:\Users\user\PycharmProjects\python_basic_diploma\handlers\default_handlers\start_commands.py", line 25, in start_command_handler
    User(user_id=user_id, username=username, first_name=first_name, last_name=last_name).save()
  File "C:\Users\user\PycharmProjects\python_basic_diploma\venv\Lib\site-packages\peewee.py", line 6806, in save
    pk = self.insert(**field_dict).execute()
         ^^^^^^^^^^^^^^^^^^^^^^^^^^^^^^^^^^^
  File "C:\Users\user\PycharmProjects\python_basic_diploma\venv\Lib\site-packages\peewee.py", line 1971, in inner
    return method(self, database, *args, **kwargs)
           ^^^^^^^^^^^^^^^^^^^^^^^^^^^^^^^^^^^^^^^
  File "C:\Users\user\PycharmProjects\python_basic_diploma\venv\Lib\site-packages\peewee.py", line 2042, in execute
    return self._execute(database)
           ^^^^^^^^^^^^^^^^^^^^^^^
  File "C:\Users\user\PycharmProjects\python_basic_diploma\venv\Lib\site-packages\peewee.py", line 2847, in _execute
    return super(Insert, self)._execute(database)
           ^^^^^^^^^^^^^^^^^^^^^^^^^^^^^^^^^^^^^^
  File "C:\Users\user\PycharmProjects\python_basic_diploma\venv\Lib\site-packages\peewee.py", line 2560, in _execute
    cursor = database.execute(self)
             ^^^^^^^^^^^^^^^^^^^^^^
  File "C:\Users\user\PycharmProjects\python_basic_diploma\venv\Lib\site-packages\peewee.py", line 3259, in execute
    return self.execute_sql(sql, params)
           ^^^^^^^^^^^^^^^^^^^^^^^^^^^^^
  File "C:\Users\user\PycharmProjects\python_basic_diploma\venv\Lib\site-packages\peewee.py", line 3249, in execute_sql
    with __exception_wrapper__:
  File "C:\Users\user\PycharmProjects\python_basic_diploma\venv\Lib\site-packages\peewee.py", line 3019, in __exit__
    reraise(new_type, new_type(exc_value, *exc_args), traceback)
  File "C:\Users\user\PycharmProjects\python_basic_diploma\venv\Lib\site-packages\peewee.py", line 192, in reraise
    raise value.with_traceback(tb)
  File "C:\Users\user\PycharmProjects\python_basic_diploma\venv\Lib\site-packages\peewee.py", line 3251, in execute_sql
    cursor.execute(sql, params or ())
peewee.IntegrityError: UNIQUE constraint failed: user.user_id



Mon Dec 11 13:16:32 2023
IntegrityError
Traceback (most recent call last):
  File "C:\Users\user\PycharmProjects\python_basic_diploma\venv\Lib\site-packages\peewee.py", line 3251, in execute_sql
    cursor.execute(sql, params or ())
sqlite3.IntegrityError: UNIQUE constraint failed: user.user_id

During handling of the above exception, another exception occurred:

Traceback (most recent call last):
  File "C:\Users\user\PycharmProjects\python_basic_diploma\handlers\default_handlers\exception_handler.py", line 17, in wrapped
    method(message)
  File "C:\Users\user\PycharmProjects\python_basic_diploma\handlers\default_handlers\start_commands.py", line 25, in start_command_handler
    User(user_id=user_id, username=username, first_name=first_name, last_name=last_name).save()
  File "C:\Users\user\PycharmProjects\python_basic_diploma\venv\Lib\site-packages\peewee.py", line 6806, in save
    pk = self.insert(**field_dict).execute()
         ^^^^^^^^^^^^^^^^^^^^^^^^^^^^^^^^^^^
  File "C:\Users\user\PycharmProjects\python_basic_diploma\venv\Lib\site-packages\peewee.py", line 1971, in inner
    return method(self, database, *args, **kwargs)
           ^^^^^^^^^^^^^^^^^^^^^^^^^^^^^^^^^^^^^^^
  File "C:\Users\user\PycharmProjects\python_basic_diploma\venv\Lib\site-packages\peewee.py", line 2042, in execute
    return self._execute(database)
           ^^^^^^^^^^^^^^^^^^^^^^^
  File "C:\Users\user\PycharmProjects\python_basic_diploma\venv\Lib\site-packages\peewee.py", line 2847, in _execute
    return super(Insert, self)._execute(database)
           ^^^^^^^^^^^^^^^^^^^^^^^^^^^^^^^^^^^^^^
  File "C:\Users\user\PycharmProjects\python_basic_diploma\venv\Lib\site-packages\peewee.py", line 2560, in _execute
    cursor = database.execute(self)
             ^^^^^^^^^^^^^^^^^^^^^^
  File "C:\Users\user\PycharmProjects\python_basic_diploma\venv\Lib\site-packages\peewee.py", line 3259, in execute
    return self.execute_sql(sql, params)
           ^^^^^^^^^^^^^^^^^^^^^^^^^^^^^
  File "C:\Users\user\PycharmProjects\python_basic_diploma\venv\Lib\site-packages\peewee.py", line 3249, in execute_sql
    with __exception_wrapper__:
  File "C:\Users\user\PycharmProjects\python_basic_diploma\venv\Lib\site-packages\peewee.py", line 3019, in __exit__
    reraise(new_type, new_type(exc_value, *exc_args), traceback)
  File "C:\Users\user\PycharmProjects\python_basic_diploma\venv\Lib\site-packages\peewee.py", line 192, in reraise
    raise value.with_traceback(tb)
  File "C:\Users\user\PycharmProjects\python_basic_diploma\venv\Lib\site-packages\peewee.py", line 3251, in execute_sql
    cursor.execute(sql, params or ())
peewee.IntegrityError: UNIQUE constraint failed: user.user_id



Mon Dec 11 13:16:32 2023
IntegrityError
Traceback (most recent call last):
  File "C:\Users\user\PycharmProjects\python_basic_diploma\venv\Lib\site-packages\peewee.py", line 3251, in execute_sql
    cursor.execute(sql, params or ())
sqlite3.IntegrityError: UNIQUE constraint failed: user.user_id

During handling of the above exception, another exception occurred:

Traceback (most recent call last):
  File "C:\Users\user\PycharmProjects\python_basic_diploma\handlers\default_handlers\exception_handler.py", line 17, in wrapped
    method(message)
  File "C:\Users\user\PycharmProjects\python_basic_diploma\handlers\default_handlers\start_commands.py", line 25, in start_command_handler
    User(user_id=user_id, username=username, first_name=first_name, last_name=last_name).save()
  File "C:\Users\user\PycharmProjects\python_basic_diploma\venv\Lib\site-packages\peewee.py", line 6806, in save
    pk = self.insert(**field_dict).execute()
         ^^^^^^^^^^^^^^^^^^^^^^^^^^^^^^^^^^^
  File "C:\Users\user\PycharmProjects\python_basic_diploma\venv\Lib\site-packages\peewee.py", line 1971, in inner
    return method(self, database, *args, **kwargs)
           ^^^^^^^^^^^^^^^^^^^^^^^^^^^^^^^^^^^^^^^
  File "C:\Users\user\PycharmProjects\python_basic_diploma\venv\Lib\site-packages\peewee.py", line 2042, in execute
    return self._execute(database)
           ^^^^^^^^^^^^^^^^^^^^^^^
  File "C:\Users\user\PycharmProjects\python_basic_diploma\venv\Lib\site-packages\peewee.py", line 2847, in _execute
    return super(Insert, self)._execute(database)
           ^^^^^^^^^^^^^^^^^^^^^^^^^^^^^^^^^^^^^^
  File "C:\Users\user\PycharmProjects\python_basic_diploma\venv\Lib\site-packages\peewee.py", line 2560, in _execute
    cursor = database.execute(self)
             ^^^^^^^^^^^^^^^^^^^^^^
  File "C:\Users\user\PycharmProjects\python_basic_diploma\venv\Lib\site-packages\peewee.py", line 3259, in execute
    return self.execute_sql(sql, params)
           ^^^^^^^^^^^^^^^^^^^^^^^^^^^^^
  File "C:\Users\user\PycharmProjects\python_basic_diploma\venv\Lib\site-packages\peewee.py", line 3249, in execute_sql
    with __exception_wrapper__:
  File "C:\Users\user\PycharmProjects\python_basic_diploma\venv\Lib\site-packages\peewee.py", line 3019, in __exit__
    reraise(new_type, new_type(exc_value, *exc_args), traceback)
  File "C:\Users\user\PycharmProjects\python_basic_diploma\venv\Lib\site-packages\peewee.py", line 192, in reraise
    raise value.with_traceback(tb)
  File "C:\Users\user\PycharmProjects\python_basic_diploma\venv\Lib\site-packages\peewee.py", line 3251, in execute_sql
    cursor.execute(sql, params or ())
peewee.IntegrityError: UNIQUE constraint failed: user.user_id



Mon Dec 11 13:19:32 2023
KeyError
Traceback (most recent call last):
  File "C:\Users\user\PycharmProjects\python_basic_diploma\handlers\additional_handlers\price_rating.py", line 19, in main_search_command
    data["cond2"] = "_less_than"
    ~~~~^^^^^^^^^
TypeError: 'NoneType' object does not support item assignment

During handling of the above exception, another exception occurred:

Traceback (most recent call last):
  File "C:\Users\user\PycharmProjects\python_basic_diploma\handlers\default_handlers\exception_handler.py", line 20, in wrapped
    method(message)
  File "C:\Users\user\PycharmProjects\python_basic_diploma\handlers\additional_handlers\price_rating.py", line 17, in main_search_command
    with bot.retrieve_data(user_id=user_id, chat_id=chat_id) as data:
  File "C:\Users\user\PycharmProjects\python_basic_diploma\venv\Lib\site-packages\telebot\storage\base_storage.py", line 68, in __exit__
    return self.obj.save(self.chat_id, self.user_id, self.data)
           ^^^^^^^^^^^^^^^^^^^^^^^^^^^^^^^^^^^^^^^^^^^^^^^^^^^^
  File "C:\Users\user\PycharmProjects\python_basic_diploma\venv\Lib\site-packages\telebot\storage\memory_storage.py", line 69, in save
    self.data[chat_id][user_id]['data'] = data
    ~~~~~~~~~^^^^^^^^^
KeyError: 439024736



Mon Dec 11 13:20:16 2023
KeyError
Traceback (most recent call last):
  File "C:\Users\user\PycharmProjects\python_basic_diploma\handlers\additional_handlers\price_rating.py", line 19, in main_search_command
    data["cond2"] = "_less_than"
    ~~~~^^^^^^^^^
TypeError: 'NoneType' object does not support item assignment

During handling of the above exception, another exception occurred:

Traceback (most recent call last):
  File "C:\Users\user\PycharmProjects\python_basic_diploma\handlers\default_handlers\exception_handler.py", line 20, in wrapped
    method(message)
  File "C:\Users\user\PycharmProjects\python_basic_diploma\handlers\additional_handlers\price_rating.py", line 17, in main_search_command
    with bot.retrieve_data(user_id=user_id, chat_id=chat_id) as data:
  File "C:\Users\user\PycharmProjects\python_basic_diploma\venv\Lib\site-packages\telebot\storage\base_storage.py", line 68, in __exit__
    return self.obj.save(self.chat_id, self.user_id, self.data)
           ^^^^^^^^^^^^^^^^^^^^^^^^^^^^^^^^^^^^^^^^^^^^^^^^^^^^
  File "C:\Users\user\PycharmProjects\python_basic_diploma\venv\Lib\site-packages\telebot\storage\memory_storage.py", line 69, in save
    self.data[chat_id][user_id]['data'] = data
    ~~~~~~~~~^^^^^^^^^
KeyError: 439024736



Mon Dec 11 13:21:26 2023
KeyError
Traceback (most recent call last):
  File "C:\Users\user\PycharmProjects\python_basic_diploma\handlers\default_handlers\search_commands.py", line 22, in search_command_handler
    data["search_cond"] = msg_user
    ~~~~^^^^^^^^^^^^^^^
TypeError: 'NoneType' object does not support item assignment

During handling of the above exception, another exception occurred:

Traceback (most recent call last):
  File "C:\Users\user\PycharmProjects\python_basic_diploma\handlers\default_handlers\exception_handler.py", line 20, in wrapped
    method(message)
  File "C:\Users\user\PycharmProjects\python_basic_diploma\handlers\default_handlers\search_commands.py", line 21, in search_command_handler
    with bot.retrieve_data(user_id=user_id, chat_id=chat_id) as data:
  File "C:\Users\user\PycharmProjects\python_basic_diploma\venv\Lib\site-packages\telebot\storage\base_storage.py", line 68, in __exit__
    return self.obj.save(self.chat_id, self.user_id, self.data)
           ^^^^^^^^^^^^^^^^^^^^^^^^^^^^^^^^^^^^^^^^^^^^^^^^^^^^
  File "C:\Users\user\PycharmProjects\python_basic_diploma\venv\Lib\site-packages\telebot\storage\memory_storage.py", line 69, in save
    self.data[chat_id][user_id]['data'] = data
    ~~~~~~~~~^^^^^^^^^
KeyError: 439024736



Mon Dec 11 13:22:55 2023
KeyError
Traceback (most recent call last):
  File "C:\Users\user\PycharmProjects\python_basic_diploma\handlers\additional_handlers\price_rating.py", line 19, in main_search_command
    data["cond2"] = "_less_than"
    ~~~~^^^^^^^^^
TypeError: 'NoneType' object does not support item assignment

During handling of the above exception, another exception occurred:

Traceback (most recent call last):
  File "C:\Users\user\PycharmProjects\python_basic_diploma\handlers\default_handlers\exception_handler.py", line 20, in wrapped
    method(message)
  File "C:\Users\user\PycharmProjects\python_basic_diploma\handlers\additional_handlers\price_rating.py", line 17, in main_search_command
    with bot.retrieve_data(user_id=user_id, chat_id=chat_id) as data:
  File "C:\Users\user\PycharmProjects\python_basic_diploma\venv\Lib\site-packages\telebot\storage\base_storage.py", line 68, in __exit__
    return self.obj.save(self.chat_id, self.user_id, self.data)
           ^^^^^^^^^^^^^^^^^^^^^^^^^^^^^^^^^^^^^^^^^^^^^^^^^^^^
  File "C:\Users\user\PycharmProjects\python_basic_diploma\venv\Lib\site-packages\telebot\storage\memory_storage.py", line 69, in save
    self.data[chat_id][user_id]['data'] = data
    ~~~~~~~~~^^^^^^^^^
KeyError: 439024736



Mon Dec 11 13:26:09 2023
KeyError
Traceback (most recent call last):
  File "C:\Users\user\PycharmProjects\python_basic_diploma\handlers\additional_handlers\price_rating.py", line 19, in main_search_command
    data["cond2"] = "_less_than"
    ~~~~^^^^^^^^^
TypeError: 'NoneType' object does not support item assignment

During handling of the above exception, another exception occurred:

Traceback (most recent call last):
  File "C:\Users\user\PycharmProjects\python_basic_diploma\handlers\default_handlers\exception_handler.py", line 20, in wrapped
    method(message)
  File "C:\Users\user\PycharmProjects\python_basic_diploma\handlers\additional_handlers\price_rating.py", line 17, in main_search_command
    with bot.retrieve_data(user_id=user_id, chat_id=chat_id) as data:
  File "C:\Users\user\PycharmProjects\python_basic_diploma\venv\Lib\site-packages\telebot\storage\base_storage.py", line 68, in __exit__
    return self.obj.save(self.chat_id, self.user_id, self.data)
           ^^^^^^^^^^^^^^^^^^^^^^^^^^^^^^^^^^^^^^^^^^^^^^^^^^^^
  File "C:\Users\user\PycharmProjects\python_basic_diploma\venv\Lib\site-packages\telebot\storage\memory_storage.py", line 69, in save
    self.data[chat_id][user_id]['data'] = data
    ~~~~~~~~~^^^^^^^^^
KeyError: 439024736



Mon Dec 11 13:40:57 2023
KeyError
Traceback (most recent call last):
  File "C:\Users\user\PycharmProjects\python_basic_diploma\handlers\default_handlers\search_commands.py", line 22, in search_command_handler
    data["search_cond"] = msg_user
    ~~~~^^^^^^^^^^^^^^^
TypeError: 'NoneType' object does not support item assignment

During handling of the above exception, another exception occurred:

Traceback (most recent call last):
  File "C:\Users\user\PycharmProjects\python_basic_diploma\handlers\default_handlers\exception_handler.py", line 20, in wrapped
    method(message)
  File "C:\Users\user\PycharmProjects\python_basic_diploma\handlers\default_handlers\search_commands.py", line 21, in search_command_handler
    with bot.retrieve_data(user_id=user_id, chat_id=chat_id) as data:
  File "C:\Users\user\PycharmProjects\python_basic_diploma\venv\Lib\site-packages\telebot\storage\base_storage.py", line 68, in __exit__
    return self.obj.save(self.chat_id, self.user_id, self.data)
           ^^^^^^^^^^^^^^^^^^^^^^^^^^^^^^^^^^^^^^^^^^^^^^^^^^^^
  File "C:\Users\user\PycharmProjects\python_basic_diploma\venv\Lib\site-packages\telebot\storage\memory_storage.py", line 69, in save
    self.data[chat_id][user_id]['data'] = data
    ~~~~~~~~~^^^^^^^^^
KeyError: 439024736



Mon Dec 11 13:47:34 2023
KeyError
Traceback (most recent call last):
  File "C:\Users\user\PycharmProjects\python_basic_diploma\handlers\default_handlers\search_commands.py", line 22, in search_command_handler
    data["search_cond"] = msg_user
    ~~~~^^^^^^^^^^^^^^^
TypeError: 'NoneType' object does not support item assignment

During handling of the above exception, another exception occurred:

Traceback (most recent call last):
  File "C:\Users\user\PycharmProjects\python_basic_diploma\handlers\default_handlers\exception_handler.py", line 20, in wrapped
    method(message)
  File "C:\Users\user\PycharmProjects\python_basic_diploma\handlers\default_handlers\search_commands.py", line 21, in search_command_handler
    with bot.retrieve_data(user_id=user_id, chat_id=chat_id) as data:
  File "C:\Users\user\PycharmProjects\python_basic_diploma\venv\Lib\site-packages\telebot\storage\base_storage.py", line 68, in __exit__
    return self.obj.save(self.chat_id, self.user_id, self.data)
           ^^^^^^^^^^^^^^^^^^^^^^^^^^^^^^^^^^^^^^^^^^^^^^^^^^^^
  File "C:\Users\user\PycharmProjects\python_basic_diploma\venv\Lib\site-packages\telebot\storage\memory_storage.py", line 69, in save
    self.data[chat_id][user_id]['data'] = data
    ~~~~~~~~~^^^^^^^^^
KeyError: 439024736



Tue Dec 12 13:53:59 2023
KeyError
Traceback (most recent call last):
  File "C:\Users\user\PycharmProjects\python_basic_diploma\handlers\default_handlers\search_commands.py", line 22, in search_command_handler
    data["search_cond"] = msg_user
    ~~~~^^^^^^^^^^^^^^^
TypeError: 'NoneType' object does not support item assignment

During handling of the above exception, another exception occurred:

Traceback (most recent call last):
  File "C:\Users\user\PycharmProjects\python_basic_diploma\handlers\default_handlers\exception_handler.py", line 20, in wrapped
    method(message)
  File "C:\Users\user\PycharmProjects\python_basic_diploma\handlers\default_handlers\search_commands.py", line 21, in search_command_handler
    with bot.retrieve_data(user_id=user_id, chat_id=chat_id) as data:
  File "C:\Users\user\PycharmProjects\python_basic_diploma\venv\Lib\site-packages\telebot\storage\base_storage.py", line 68, in __exit__
    return self.obj.save(self.chat_id, self.user_id, self.data)
           ^^^^^^^^^^^^^^^^^^^^^^^^^^^^^^^^^^^^^^^^^^^^^^^^^^^^
  File "C:\Users\user\PycharmProjects\python_basic_diploma\venv\Lib\site-packages\telebot\storage\memory_storage.py", line 69, in save
    self.data[chat_id][user_id]['data'] = data
    ~~~~~~~~~^^^^^^^^^
KeyError: 439024736



Tue Dec 12 14:18:35 2023
KeyError
Traceback (most recent call last):
  File "C:\Users\user\PycharmProjects\python_basic_diploma\handlers\default_handlers\search_commands.py", line 22, in search_command_handler
    data["search_cond"] = msg_user
    ~~~~^^^^^^^^^^^^^^^
TypeError: 'NoneType' object does not support item assignment

During handling of the above exception, another exception occurred:

Traceback (most recent call last):
  File "C:\Users\user\PycharmProjects\python_basic_diploma\handlers\default_handlers\exception_handler.py", line 20, in wrapped
    method(message)
  File "C:\Users\user\PycharmProjects\python_basic_diploma\handlers\default_handlers\search_commands.py", line 21, in search_command_handler
    with bot.retrieve_data(user_id=user_id, chat_id=chat_id) as data:
  File "C:\Users\user\PycharmProjects\python_basic_diploma\venv\Lib\site-packages\telebot\storage\base_storage.py", line 68, in __exit__
    return self.obj.save(self.chat_id, self.user_id, self.data)
           ^^^^^^^^^^^^^^^^^^^^^^^^^^^^^^^^^^^^^^^^^^^^^^^^^^^^
  File "C:\Users\user\PycharmProjects\python_basic_diploma\venv\Lib\site-packages\telebot\storage\memory_storage.py", line 69, in save
    self.data[chat_id][user_id]['data'] = data
    ~~~~~~~~~^^^^^^^^^
KeyError: 439024736



